Workbook
Name ReservaLegal: Caratula!$24:$24
Name Capital: Caratula!$22:$22
Name PasivoNoCorr: Caratula!$19:$19
Name high: Altman!$D$4:$D$11
Name zeta4: Caratula!$59:$59
Name OtrosPatrimonio: Caratula!$23:$23
Name ROA: Caratula!$44:$44
Name CTrabajo: Caratula!$30:$30
Name RotaInventarios: Caratula!$33:$33
Name ApalancaBca: Caratula!$40:$40
Name altman2: Altman!$I$4:$I$11
Name ROE: Caratula!$43:$43
Name CrecVentas: Caratula!$42:$42
Name izsel: Caratula!$C$62:$C$69
Name Acida: Caratula!$29:$29
Name Cajaendias: Caratula!$36:$36
Name altman4: Altman!$K$4:$K$11
Name PasivoTotal: Caratula!$20:$20
Name PasivoCorr: Caratula!$18:$18
Name Liquidez: Caratula!$28:$28
Name zeta3: Caratula!$58:$58
Name ApalancaCom: Caratula!$41:$41
Name UtilidadRetenida: Caratula!$25:$25
Name Cobrodias: Caratula!$32:$32
Name low: Altman!$C$4:$C$11
Name zeta5: Caratula!$60:$60
Name ActivoCorr: Caratula!$13:$13
Name altman3: Altman!$J$4:$J$11
Name altman1: Altman!$H$4:$H$11
Name UtilidadNeta: Caratula!$11:$11
Name Inventarios: Balance!$18:$18
Name Patrimonio: Caratula!$26:$26
Name Ventas: Caratula!$10:$10
Name altman5: Altman!$L$4:$L$11
Name Apalancamiento: Caratula!$39:$39
Name ActivoTotal: Caratula!$16:$16
Name EBITDA: Caratula!$37:$37
Name zeta2: Caratula!$57:$57
Name sel: Caratula!$B$71
Name ActivoNoCorr: Caratula!$14:$14
Name ActDiferido: Caratula!$15:$15
Name Pagoendias: Caratula!$34:$34
Name zeta1: Caratula!$56:$56

Sheet Caratula
D1: LU3-American Medical Enterprises | K1: LU4-Novoswiss PFJuridica | Q1: LU2-Luminova PFJuridica | V1: LU1-Helvetia PFJuridica | AA1: ETI-Corp Etisa 2025 vf | AF1: Bahía Colorada | AJ1: Soluciones Carnicas | AM1: Servicios y Perecederos | AQ1: Quimica Total | AU1: Logistica Nave | AY1: Inversiones Iginia | BD1: Ing_Palo_Gordo | BI1: Distribuidora Me Llega | BM1: Corinco | BQ1: Inversiones Mapakhan, S.A. | BT1: Corporación Mogori
D2: 2020 | E2: 2021 | F2: 2022 | G2: 2023 | H2: 2024 | J2: 2020 | K2: 2021 | L2: 2022 | M2: 2023 | N2: 2024 | P2: 2020 | Q2: 2021 | R2: 2022 | S2: 2023 | T2: 2024 | V2: 2021 | W2: 2022 | X2: 2023 | Y2: 2024 | AA2: 2021 | AB2: 2022 | AC2: 2023 | AD2: 2024 | AF2: 2021 | AG2: 2022 | AH2: 2023 | AJ2: 2022 | AK2: 2023 | AM2: 2021 | AN2: 2022 | AO2: 2023 | AQ2: 2022 | AR2: 2023 | AS2: 2024 | AU2: 2022 | AV2: 2023 | AW2: 2024 | AY2: 2020 | AZ2: 2021 | BA2: 2022 | BB2: 2023 | BD2: 2021 | BE2: 2022 | BF2: 2023 | BG2: 2024 | BI2: 2022 | BJ2: 2023 | BK2: 2024 | BM2: 2021 | BN2: 2022 | BO2: 2023 | BQ2: 2021 | BR2: 2022 | BT2: 2021 | BU2: 2022 | BV2: 2023
D3: Auditado | E3: Auditado | F3: Auditado | G3: Auditado | H3: Admin. | J3: Auditado | K3: Auditado | L3: Auditado | M3: Auditado | N3: Admin. | P3: Auditado | Q3: Auditado | R3: Auditado | S3: Admin. | T3: Admin. | V3: Auditado | W3: Auditado | X3: Auditado | Y3: Admin. | AA3: Pendiente | AB3: Auditado | AC3: Auditado | AD3: Admin. | AF3: Auditado | AG3: Auditado | AH3: Administrativo | AJ3: Administrativo | AK3: Administrativo | AM3: Auditado | AN3: Auditado | AO3: Administrativo | AQ3: Administrativo | AR3: Administrativo | AS3: Administrativo | AU3: Auditado | AV3: Auditado | AW3: Administrativo | AY3: Auditado | AZ3: Auditado | BA3: Auditado | BB3: Auditado | BD3: Auditado | BE3: Auditado | BF3: Auditado | BG3: Administrativo | BI3: Auditado | BJ3: Auditado | BK3: Administrativo | BM3: Administrativo | BN3: Administrativo | BO3: Administrativo | BQ3: Administrativo | BR3: Administrativo | BT3: Administrativo | BU3: Administrativo | BV3: Administrativo
A5: NOMBRE DEL CLIENTE: | D5: LU3-American Medical Enterprises | K5: LU4-Novoswiss PFJuridica | Q5: LU2-Luminova PFJuridica | V5: LU1-Helvetia PFJuridica | AA5: ETI-Corp Etisa 2025 vf | AF5: Bahía Colorada, S.A. | AJ5: Soluciones Carnicas de Guatemala, S.A. | AM5: Servicios y Perecederos | AQ5: QUIMICA TOTAL, S.A. | AU5: LOGISTICA NAVE, S.A. | AY5: INVERSIONES IGINLA, S.A. | BD5: Ingenio Palo Gordo, S.A. | BI5: Distribuidora Me Llega, S.A. | BM5: Corinco, S.A. | BQ5: Inversiones Mapakhan, S.A.
A6: GIRO DEL NEGOCIO: | J6: Importación, exportación, fabricación y distribución de toda clase de medicamentos | P6: Venta de medicamentos | V6: Importación, fabricación y distribución de medicamentos y productos dietéticos | AA6: Impresión de etiquetas, viñetas o cualquier clase de impresión | AF6: Planificación, desarrollo, ejecución y promoción de urbanizaciones, lotificaciones | AJ6: Venta de productos carnicos | AQ6: INDUSTRIA DE QUIMICOS | AU6: Prestación de servicios de importación, bodegas, maquila y logistica de todo tipo de productos. | AY6: Compra, venta y distibución e importación de accesorios, respuestos y máquinaria para industria automotriz. | BD6: Tiene como actividad principal la fabricación y venta loca y del exterior de acucar, melaza y alcohol, los cuales son productos del proceso de la caña de azucar. Así como la cogeneración y venta de energía electríca. | BI6: Compra, venta y comercialización de productos alimenticios, de belleza, de hogar. | BM6: Producción de empaques plasticos de agroindustrua y comercio | BQ6: Importación, exportacion, maquila, comercializacion y venta de todo tipo de Juguetes y de juegos.
A7: EN MILES DE: | D7: Dólares | J7: QUETZALES | P7: QUETZALES | V7: QUETZALES | AA7: QUETZALES | AF7: QUETZALES | AJ7: QUETZALES | AQ7: QUETZALES | AU7: QUETZALES | AY7: QUETZALES | BD7: QUETZALES | BI7: QUETZALES | BM7: QUETZALES | BQ7: QUETZALES
A8: FIRMA DE AUDITORIA (O CONTADOR): | D8: Axel Samuel Rosas | J8: Axel Samuel Rosas | P8: Axel Samuel Rosas | V8: Axel Samuel Rosas | AA8: Mynor Armando Alacan Morales | AF8: Lic. Edwin R. Hernandez B. | AJ8: Hugo Waldermar Sutuj Chamale | AQ8: Jorge Eduardo Motta Morales | AU8: Nexia | AY8: Lic. Oscar Saul Rodríguez Lemus | BD8: PKF | BI8: Nexia | BM8: Miguel Miculax Olcot | BQ8: Sergio Armando Mancilla López
A10: Ventas | D10: 23930.151 | E10: 23578.78 | F10: 29792.243 | G10: 32768.103 | H10: 24145.584 | J10: 337466 | K10: 330048 | L10: 360978.12 | M10: 419772.2 | N10: 312105.95 | P10: 4317 | Q10: 70441.169 | R10: 103822.19 | S10: 109585.88 | T10: 75793.976 | V10: 20425.762 | W10: 33740.045 | X10: 42955.437 | Y10: 33868.198 | AA10: 0 | AB10: 39281.699 | AC10: 52097.658 | AD10: 54416.681 | AF10: 0 | AG10: 84.33 | AH10: 41.09 | AJ10: 0 | AK10: 7801.0852 | AM10: 78485.195 | AN10: 87117.634 | AO10: 44163.718 | AQ10: 82237.533 | AR10: 68840.543 | AS10: 19674.964 | AU10: 121315.38 | AV10: 202588.23 | AW10: 261570.89 | AY10: 5447.2655 | AZ10: 2139.0766 | BA10: 11106.372 | BB10: 24713.03 | BD10: 866642.62 | BE10: 1060188.4 | BF10: 1102452.7 | BG10: 965922.81 | BI10: 1222964.8 | BJ10: 1675859.3 | BK10: 2072384.5 | BM10: 15793.657 | BN10: 20165.228 | BO10: 24153.542 | BQ10: 2842.924 | BR10: 4509.4649 | BT10: 14171.65 | BU10: 22085.897 | BV10: 25741.048
A11: Utilidad Neta | D11: 14418.686 | E11: 2893.883 | F11: 5234.476 | G11: 6219.504 | H11: 3790.438 | J11: 19435 | K11: 21414 | L11: 16122.97 | M11: 7214.951 | N11: 2151.953 | P11: -2996 | Q11: 1275.956 | R11: 2586.204 | S11: 4571.311 | T11: -2835.862 | V11: -35.504 | W11: -2708.358 | X11: 711.661 | Y11: 1111.626 | AA11: 0 | AB11: 1160.272 | AC11: 887.238 | AD11: 2968.52 | AF11: -0.28 | AG11: 5.53129 | AH11: 1.85184 | AJ11: -519.13544 | AK11: 1232.1515 | AM11: 4380.6467 | AN11: 4565.6092 | AO11: 2065.929 | AQ11: 7054.376 | AR11: 4141.618 | AS11: 1335.7 | AU11: 12848.287 | AV11: 23613.1 | AW11: 33959.983 | AY11: 20.594914 | AZ11: 609.10853 | BA11: 2768.891 | BB11: 5028.2748 | BD11: 7083.423 | BE11: 17602.676 | BF11: 44943.41 | BG11: 3219.1304 | BI11: -10822.811 | BJ11: -37184.829 | BK11: 11939.541 | BM11: 1764.4344 | BN11: 2457.77 | BO11: 3680.8237 | BQ11: 64.311 | BR11: 269.01435 | BT11: 371.763 | BU11: 2177.1423 | BV11: 2076.6117
A13: Activo Corriente | D13: 21443.876 | E13: 16147.77 | F13: 27257.998 | G13: 30188.632 | H13: 28923.839 | J13: 489171 | K13: 559173 | L13: 658388.66 | M13: 747714.18 | N13: 731542.08 | P13: 156739.98 | Q13: 50343.569 | R13: 69251.927 | S13: 80296.962 | T13: 89011.252 | V13: 17118.68 | W13: 22603.33 | X13: 41829.318 | Y13: 22008.315 | AA13: 4149 | AB13: 55862.546 | AC13: 47567.44 | AD13: 53771.717 | AF13: 16158.428 | AG13: 16137.416 | AH13: 16139.218 | AJ13: 5 | AK13: 18025.535 | AM13: 49728.769 | AN13: 62872.607 | AO13: 56280.634 | AQ13: 59812.929 | AR13: 77391.045 | AS13: 74316.734 | AU13: 489257.84 | AV13: 495285.08 | AW13: 460780.22 | AY13: 20834.299 | AZ13: 37591.151 | BA13: 57469.938 | BB13: 68526.191 | BD13: 1207333.4 | BE13: 1247545.1 | BF13: 1252652.1 | BG13: 1294259.4 | BI13: 403277.95 | BJ13: 537700.31 | BK13: 710962.57 | BM13: 10197.616 | BN13: 12016.524 | BO13: 16407.74 | BQ13: 407.668 | BR13: 2554.7835 | BT13: 6856.8995 | BU13: 11124.908 | BV13: 15295.218
A14: Activo No Corriente | D14: 0 | E14: 0 | F14: 0 | G14: 0 | H14: 0 | J14: 117278.28 | K14: 105337 | L14: 183901.7 | M14: 221052.02 | N14: 95615.306 | P14: 25948 | Q14: 26300.778 | R14: 23715.271 | S14: 28567.047 | T14: 29221.778 | V14: 45079.636 | W14: 2661.033 | X14: 3208.322 | Y14: 5083.783 | AA14: 0 | AB14: 11951.704 | AC14: 10657.175 | AD14: 10971.355 | AF14: 1937.5 | AG14: 1937.5 | AH14: 1937.5 | AJ14: 0 | AK14: 129.08187 | AM14: 16347.708 | AN14: 18501.092 | AO14: 20780.629 | AQ14: 1807.105 | AR14: 1742.831 | AS14: 1813.014 | AU14: 71490.305 | AV14: 102640.33 | AW14: 116100.16 | AY14: 495.56997 | AZ14: 195.31259 | BA14: 1469.1188 | BB14: 2981.4867 | BD14: 1074320.7 | BE14: 988756.83 | BF14: 991524.48 | BG14: 1035248.8 | BI14: 2157.85 | BJ14: 6069.277 | BK14: 19132.291 | BM14: 3591.4617 | BN14: 3841.6349 | BO14: 6142.7224 | BQ14: 3.33248 | BR14: 27.64633 | BT14: 44.108 | BU14: 47.24313 | BV14: 121.70389
A15: Activo Diferido | D15: 43854.634 | E15: 47511.01 | F15: 43317.688 | G15: 51328.915 | H15: 73222.413 | J15: 316380 | K15: 332106 | L15: 269491.19 | M15: 282184.37 | N15: 442297.11 | P15: 34413 | Q15: 162778.8 | R15: 148720.9 | S15: 154873.23 | T15: 168630.21 | V15: 0 | W15: 0 | X15: 0 | Y15: 31265.551 | AA15: 0 | AB15: 11319.385 | AC15: 20216.327 | AD15: 14995.304 | AF15: 0 | AG15: 0 | AH15: 0 | AJ15: 7.5 | AK15: 7.5 | AM15: 4372.5589 | AN15: 2125.3835 | AO15: 2125.3849 | AQ15: 12.811 | AR15: 250.039 | AS15: 235.915 | AU15: 3297.461 | AV15: 4455.227 | AW15: 5384.058 | AY15: 2141.2416 | AZ15: 1956.096 | BA15: 1770.9504 | BB15: 1585.8048 | BD15: 132202.72 | BE15: 135392.1 | BF15: 119134.51 | BG15: 98694.956 | BI15: 5951.627 | BJ15: 5951.627 | BK15: 5951.627 | BM15: 0 | BN15: 0 | BO15: 0 | BQ15: 0 | BR15: 0 | BT15: 0 | BU15: 0 | BV15: 0
A16: Total de Activo | D16: 65298.51 | E16: 63658.78 | F16: 70575.686 | G16: 81517.547 | H16: 102146.25 | J16: 922829.28 | K16: 996616 | L16: 1111781.5 | M16: 1250950.6 | N16: 1269454.5 | P16: 217100.98 | Q16: 239423.14 | R16: 241688.1 | S16: 263737.24 | T16: 286863.24 | V16: 62198.316 | W16: 25264.363 | X16: 45037.64 | Y16: 58357.649 | AA16: 4149 | AB16: 79133.635 | AC16: 78440.942 | AD16: 79738.376 | AF16: 18095.928 | AG16: 18074.916 | AH16: 18076.718 | AJ16: 12.5 | AK16: 18162.117 | AM16: 70449.036 | AN16: 83499.083 | AO16: 79186.648 | AQ16: 61632.845 | AR16: 79383.915 | AS16: 76365.663 | AU16: 564045.6 | AV16: 602380.64 | AW16: 582264.43 | AY16: 23471.111 | AZ16: 39742.559 | BA16: 60710.007 | BB16: 73093.482 | BD16: 2413856.8 | BE16: 2371694 | BF16: 2363311 | BG16: 2428203.1 | BI16: 411387.43 | BJ16: 549721.22 | BK16: 736046.49 | BM16: 13789.078 | BN16: 15858.159 | BO16: 22550.462 | BQ16: 411.00048 | BR16: 2582.4298 | BT16: 6901.0075 | BU16: 11172.151 | BV16: 15416.922
A18: Pasivo Corriente | D18: 40792.936 | E18: 30309.361 | F18: 38072.359 | G18: 30532.448 | H18: 41502.354 | J18: 162415 | K18: 268455 | L18: 234795.17 | M18: 277370.83 | N18: 442676.45 | P18: 35006 | Q18: 42593.636 | R18: 53598.854 | S18: 61927.296 | T18: 86036.563 | V18: 40572.929 | W18: 6092.298 | X18: 25287.61 | Y18: 21943.731 | AA18: 0 | AB18: 22040.14 | AC18: 20790.369 | AD18: 14654.413 | AF18: 0 | AG18: 0 | AH18: 0 | AJ18: 7.5 | AK18: 14330.181 | AM18: 36686.451 | AN18: 39334.017 | AO18: 39432.836 | AQ18: 7584.777 | AR18: 4763.187 | AS18: 602.094 | AU18: 43044.148 | AV18: 75189.951 | AW18: 70585.001 | AY18: 1697.3226 | AZ18: 7422.986 | BA18: 19266.655 | BB18: 22946.795 | BD18: 351927.3 | BE18: 368985 | BF18: 404572.41 | BG18: 687122.82 | BI18: 269718.17 | BJ18: 451638.98 | BK18: 626024.71 | BM18: 816.3589 | BN18: 899.5229 | BO18: 1267.1727 | BQ18: 341.97861 | BR18: 464.43575 | BT18: 2794.4995 | BU18: 8406.5064 | BV18: 2683.9404
A19: Pasivo No Corriente | D19: 10181.019 | E19: 16130.981 | F19: 10050.413 | G19: 22312.681 | H19: 21738.022 | J19: 310963 | K19: 257172 | L19: 351454.95 | M19: 411562.72 | N19: 315090.21 | P19: 45937 | Q19: 58943.814 | R19: 48747.619 | S19: 53904.635 | T19: 55329.341 | V19: 77.481 | W19: 331.962 | X19: 198.82 | Y19: 15751.093 | AA19: 0 | AB19: 20186.765 | AC19: 19842.093 | AD19: 24459.709 | AF19: 5.89476 | AG19: 0 | AH19: 0 | AJ19: 0 | AK19: 0 | AM19: 7271.0714 | AN19: 14107.943 | AO19: 10130.76 | AQ19: 25322.054 | AR19: 44035.114 | AS19: 43842.254 | AU19: 377116.73 | AV19: 359692.86 | AW19: 348368.48 | AY19: 8550 | AZ19: 20819.712 | BA19: 22472.022 | BB19: 22106.502 | BD19: 1122074.3 | BE19: 1111928.2 | BF19: 1125454.4 | BG19: 1141114.8 | BI19: 3542.761 | BJ19: 321.476 | BK19: 321.476 | BM19: 1291.9569 | BN19: 785.48835 | BO19: 3429.3175 | BQ19: 0 | BR19: 1761.4282 | BT19: 0 | BU19: 97.46402 | BV19: 8532.5861
A20: Total Pasivo | D20: 50973.955 | E20: 46440.342 | F20: 48122.772 | G20: 52845.129 | H20: 63240.376 | J20: 473378 | K20: 525627 | L20: 586250.12 | M20: 688933.55 | N20: 757766.65 | P20: 80943 | Q20: 101537.45 | R20: 102346.47 | S20: 115831.93 | T20: 141365.9 | V20: 40650.41 | W20: 6424.26 | X20: 25486.43 | Y20: 37694.824 | AA20: 0 | AB20: 42226.905 | AC20: 40632.462 | AD20: 39114.122 | AF20: 5.89476 | AG20: 0 | AH20: 0 | AJ20: 7.5 | AK20: 14330.181 | AM20: 43957.523 | AN20: 53441.961 | AO20: 49563.596 | AQ20: 32906.831 | AR20: 48798.301 | AS20: 44444.348 | AU20: 420160.88 | AV20: 434882.81 | AW20: 418953.48 | AY20: 10247.323 | AZ20: 28242.698 | BA20: 41738.677 | BB20: 45053.297 | BD20: 1474001.6 | BE20: 1480913.2 | BF20: 1530026.8 | BG20: 1828237.7 | BI20: 273260.93 | BJ20: 451960.46 | BK20: 626346.19 | BM20: 2108.3158 | BN20: 1685.0113 | BO20: 4696.4903 | BQ20: 341.97861 | BR20: 2225.864 | BT20: 2794.4995 | BU20: 8503.9704 | BV20: 11216.527
A22: Capital | J22: 114975 | K22: 114995 | L22: 114995 | M22: 114995 | N22: 114995 | P22: 128348 | Q22: 128370.97 | R22: 128397.93 | S22: 128397.93 | T22: 128414.01 | V22: 21388 | W22: 21388 | X22: 21388 | Y22: 21388 | AA22: 0 | AB22: 20598 | AC22: 20598 | AD22: 20598 | AF22: 2000 | AG22: 2000 | AH22: 2000 | AJ22: 5 | AK22: 490 | AM22: 15000 | AN22: 15000 | AO22: 15000 | AQ22: 5005 | AR22: 5005 | AS22: 5005 | AU22: 111574.8 | AV22: 111574.8 | AW22: 111574.8 | AY22: 7572.2 | AZ22: 7572.2 | BA22: 7572.2 | BB22: 16105.6 | BD22: 134051.4 | BE22: 134051.4 | BF22: 134051.4 | BG22: 134051.4 | BI22: 460989 | BJ22: 460989 | BK22: 92197.8 | BM22: 3105 | BN22: 3105 | BO22: 3105 | BQ22: 5 | BR22: 5 | BT22: 6 | BU22: 6 | BV22: 6
A23: Otros | D23: 0 | E23: 0 | F23: 0 | G23: 0 | H23: 0 | J23: 0 | K23: 0 | L23: -6800.427 | M23: 22470.203 | N23: 0 | P23: 6984 | Q23: 7515.611 | R23: 1254.59 | S23: 949.485 | T23: 3094.496 | V23: 0 | W23: 0 | X23: 0 | Y23: 0 | AA23: 0 | AB23: 0 | AC23: 0 | AD23: 5439.5 | AF23: 14879.185 | AG23: 14858.537 | AH23: 14858.257 | AJ23: 0 | AK23: 3000 | AM23: 0 | AN23: 0 | AO23: 0 | AQ23: 9995 | AR23: 9995 | AS23: 9995 | AU23: 8912.602 | AV23: 8912.602 | AW23: 13912.579 | AY23: 4838.439 | AZ23: 2473.345 | BA23: 7207.9805 | BB23: 2655.2001 | BD23: 827460.03 | BE23: 763600.52 | BF23: 641385.65 | BG23: 406960.01 | BI23: 3180.903 | BJ23: 0 | BK23: 0 | BM23: 2.8535 | BN23: 2.8535 | BO23: 2.8535 | BQ23: 0 | BR23: 0 | BT23: 0 | BU23: 0 | BV23: 0
A24: Reserva Legal | J24: 28309 | K24: 29652 | L24: 31064.837 | M24: 31778.92 | N24: 31778.92 | P24: 3668 | Q24: 3835.227 | R24: 4086.595 | S24: 4175.852 | T24: 4541.229 | V24: 71.441 | W24: 71.441 | X24: 119.549 | Y24: 119.549 | AA24: 0 | AB24: 0 | AC24: 0 | AD24: 694.589 | AF24: 44.22588 | AG24: 44.22588 | AH24: 44.22588 | AM24: 271.946 | AN24: 490.97832 | AO24: 490.97832 | AQ24: 1186.153 | AR24: 1404.133 | AS24: 1404.133 | AU24: 2164.457 | AV24: 3357.874 | AW24: 5105.494 | AY24: 46.49867 | AZ24: 78.55701 | BA24: 46.49867 | BB24: 119.76161 | BD24: 21884.101 | BE24: 22869.044 | BF24: 24625.769 | BG24: 27650.698 | BI24: 0 | BJ24: 0 | BK24: 0 | BM24: 796.52592 | BN24: 1083.2658 | BO24: 1291.8694 | BQ24: 0 | BR24: 0 | BT24: 75.655 | BU24: 112.83228 | BV24: 140.05211
A25: Utilidades Retenidas | D25: 14324.555 | E25: 17218.238 | F25: 22452.714 | G25: 28672.218 | H25: 38905.676 | J25: 306165 | K25: 326342 | L25: 386272.01 | M25: 392772.88 | N25: 364913.92 | P25: -2843 | Q25: -1836.117 | R25: 360.338 | S25: 8745.705 | T25: -4538.771 | V25: 88.465 | W25: -2619.893 | X25: -1956.339 | Y25: -844.713 | AA25: 0 | AB25: 16308.73 | AC25: 17210.48 | AD25: 13892.165 | AF25: 1166.622 | AG25: 1172.1533 | AH25: 1174.2357 | AJ25: 0 | AK25: 341.9356 | AM25: 11219.567 | AN25: 14566.144 | AO25: 14132.073 | AQ25: 12539.861 | AR25: 14181.481 | AS25: 15517.182 | AU25: 21232.865 | AV25: 43652.548 | AW25: 32718.079 | AY25: 766.65075 | AZ25: 1375.7592 | BA25: 4144.6502 | BB25: 9159.6235 | BD25: -43540.303 | BE25: -29740.147 | BF25: 33221.445 | BG25: 31303.343 | BI25: -326043.41 | BJ25: -363228.24 | BK25: 17502.502 | BM25: 7776.3825 | BN25: 9982.0288 | BO25: 13454.249 | BQ25: 64.02187 | BR25: 351.56579 | BT25: 4024.853 | BU25: 2549.3482 | BV25: 4054.3434
A26: Total Patrimonio | D26: 14324.755 | E26: 17218.438 | F26: 22452.914 | G26: 28672.418 | H26: 38905.876 | J26: 449449 | K26: 470989 | L26: 525531.42 | M26: 562017 | N26: 511687.84 | P26: 136157 | Q26: 137885.69 | R26: 139341.63 | S26: 147905.31 | T26: 145497.34 | V26: 21547.906 | W26: 18839.548 | X26: 19551.21 | Y26: 20662.836 | AA26: 0 | AB26: 36906.73 | AC26: 37808.48 | AD26: 40624.254 | AF26: 18090.033 | AG26: 18074.916 | AH26: 18076.718 | AJ26: 5 | AK26: 3831.9356 | AM26: 26491.513 | AN26: 30057.122 | AO26: 29623.051 | AQ26: 28726.014 | AR26: 30585.614 | AS26: 31921.315 | AU26: 143884.72 | AV26: 167497.82 | AW26: 163310.95 | AY26: 13223.788 | AZ26: 11499.861 | BA26: 18971.329 | BB26: 28040.185 | BD26: 939855.23 | BE26: 890780.82 | BF26: 833284.27 | BG26: 599965.45 | BI26: 138126.49 | BJ26: 97760.761 | BK26: 109700.3 | BM26: 11680.762 | BN26: 14173.148 | BO26: 17853.972 | BQ26: 69.02187 | BR26: 356.56579 | BT26: 4106.508 | BU26: 2668.1805 | BV26: 4200.3955
A28: Liquidez | D28: 0.52567621 | E28: 0.53276511 | F28: 0.71595243 | G28: 0.98873932 | H28: 0.69692044 | J28: 3.0118585 | K28: 2.0829301 | L28: 2.804098 | M28: 2.6957203 | N28: 1.6525435 | P28: 4.4775176 | Q28: 1.1819505 | R28: 1.2920412 | S28: 1.2966328 | T28: 1.0345747 | V28: 0.42192369 | W28: 3.7101485 | X28: 1.6541428 | Y28: 1.0029432 | AA28: 0 | AB28: 2.5345822 | AC28: 2.2879555 | AD28: 3.6693191 | AF28: 0 | AG28: 0 | AH28: 0 | AJ28: 0.66666667 | AK28: 1.2578721 | AM28: 1.3555077 | AN28: 1.5984283 | AO28: 1.427253 | AQ28: 7.8859179 | AR28: 16.247744 | AS28: 123.43045 | AU28: 11.366419 | AV28: 6.587118 | AW28: 6.5280188 | AY28: 12.274803 | AZ28: 5.0641548 | BA28: 2.9828705 | BB28: 2.9863077 | BD28: 3.430633 | BE28: 3.3810184 | BF28: 3.096237 | BG28: 1.8835925 | BI28: 1.4951827 | BJ28: 1.1905534 | BK28: 1.1356781 | BM28: 12.491584 | BN28: 13.358775 | BO28: 12.948305 | BQ28: 1.1920863 | BR28: 5.5008329 | BT28: 2.4537129 | BU28: 1.3233687 | BV28: 5.6987921
A29: Prueba Acida | D29: 0.52567489 | E29: 0.53276498 | F29: 0.71595243 | G29: 0.98873932 | H29: 0.69692044 | J29: 2.3167996 | K29: 1.7105176 | L29: 2.458597 | M29: 2.3510577 | N29: 1.3079216 | P29: 4.1072668 | Q29: 0.83911521 | R29: 0.97149027 | S29: 0.9002935 | T29: 0.79435734 | V29: 0.33612345 | W29: 2.8278118 | X29: 1.4480697 | Y29: 0.76047747 | AA29: 0 | AB29: 1.9549913 | AC29: 1.6244756 | AD29: 2.729427 | AF29: 0 | AG29: 0 | AH29: 0 | AJ29: 0.66666667 | AK29: 1.1576597 | AM29: 0.9476036 | AN29: 1.1982056 | AO29: 0.99051794 | AQ29: 4.7640301 | AR29: 10.203357 | AS29: 78.886338 | AU29: 11.366419 | AV29: 6.587118 | AW29: 6.5280188 | AY29: 10.49672 | AZ29: 4.7341577 | BA29: 2.7938619 | BB29: 2.6255411 | BD29: 1.9720659 | BE29: 1.8947657 | BF29: 1.5773992 | BG29: 0.67496871 | BI29: 1.1020791 | BJ29: 0.81667676 | BK29: 0.78988282 | BM29: 12.21489 | BN29: 12.9687 | BO29: 10.572202 | BQ29: 0.48450984 | BR29: 2.1821932 | BT29: 0.79278257 | BU29: 0.22593382 | BV29: 0.86151775
A30: Capital de Trabajo | D30: -19349.06 | E30: -14161.591 | F30: -10814.361 | G30: -343.816 | H30: -12578.515 | J30: 326756 | K30: 290718 | L30: 423593.49 | M30: 470343.34 | N30: 288865.64 | P30: 121733.98 | Q30: 7749.933 | R30: 15653.073 | S30: 18369.666 | T30: 2974.689 | V30: -23454.249 | W30: 16511.032 | X30: 16541.708 | Y30: 64.584 | AA30: 4149 | AB30: 33822.406 | AC30: 26777.071 | AD30: 39117.304 | AF30: 16158.428 | AG30: 16137.416 | AH30: 16139.218 | AJ30: -2.5 | AK30: 3695.3537 | AM30: 13042.317 | AN30: 23538.59 | AO30: 16847.798 | AQ30: 52228.152 | AR30: 72627.858 | AS30: 73714.64 | AU30: 446213.69 | AV30: 420095.13 | AW30: 390195.22 | AY30: 19136.977 | AZ30: 30168.165 | BA30: 38203.282 | BB30: 45579.396 | BD30: 855406.11 | BE30: 878560.08 | BF30: 848079.65 | BG30: 607136.57 | BI30: 133559.78 | BJ30: 86061.333 | BK30: 84937.86 | BM30: 9381.2572 | BN30: 11117.002 | BO30: 15140.567 | BQ30: 65.68939 | BR30: 2090.3477 | BT30: 4062.4 | BU30: 2718.4014 | BV30: 12611.278
A32: Período promedio de cobro (días) | D32: 319.0952 | E32: 232.49789 | F32: 323.72398 | G32: 326.68427 | H32: 281.4713 | J32: 256.00126 | K32: 239.33791 | L32: 487.77804 | M32: 488.48729 | N32: 370.59914 | P32: 2608.4781 | Q32: 119.01166 | R32: 125.78658 | S32: 134.70208 | T32: 165.75094 | V32: 215.46244 | W32: 141.40689 | X32: 262.41122 | Y32: 106.72672 | AA32: 0 | AB32: 281.77593 | AC32: 205.37245 | AD32: 245.89489 | AF32: 0 | AG32: 3927.4309 | AH32: 4082.8039 | AJ32: 0 | AK32: 278.94011 | AM32: 116.79459 | AN32: 154.91912 | AO32: 126.9005 | AQ32: 124.49152 | AR32: 187.1087 | AS32: 156.22171 | AU32: 61.161233 | AV32: 46.739736 | AW32: 40.58706 | AY32: 832.60672 | AZ32: 4084.6757 | BA32: 1266.8023 | BB32: 596.14415 | BD32: 38.420372 | BE32: 36.657843 | BF32: 46.8937 | BG32: 58.663567 | BI32: 63.555346 | BJ32: 64.144733 | BK32: 66.407236 | BM32: 217.87683 | BN32: 186.13114 | BO32: 180.38387 | BQ32: 2.2223598 | BR32: 45.576867 | BT32: 4.5530633 | BU32: 2.0196388 | BV32: 14.550951
A33: Rotación promedio de inventario (días) | F33: 0 | G33: 0 | H33: 0 | J33: 268.7454 | K33: 178.57197 | L33: 125.36564 | M33: 140.17304 | N33: 220.41053 | P33: 1903.6965 | Q33: 220.17859 | R33: 182.05065 | S33: 233.68608 | T33: 218.58791 | V33: 68.330869 | W33: 59.949788 | X33: 55.228232 | Y33: 57.279224 | AA33: 0 | AB33: 166.4898 | AC33: 134.80189 | AD33: 134.32265 | AM33: 96.815932 | AN33: 88.182555 | AO33: 96.010699 | AQ33: 130.20856 | AR33: 188.24076 | AS33: 164.11649 | AU33: 0 | AV33: 0 | AW33: 0 | AY33: 299.9292 | AZ33: 511.79906 | BA33: 155.98912 | BB33: 158.90599 | BD33: 257.6582 | BE33: 228.07861 | BF33: 243.24966 | BG33: 387.99361 | BI33: 38.951673 | BJ33: 44.153758 | BK33: 48.315428 | BM33: 7.5925305 | BN33: 9.6601063 | BO33: 69.126165 | BQ33: 48.679243 | BR33: 231.92323 | BT33: 194.20086 | BU33: 313.18988 | BV33: 422.75617
A34: Período promedio de pago (días) | D34: 0 | E34: 0 | F34: 0 | G34: 0 | H34: 10.618845 | J34: 64.753056 | K34: 104.0788 | L34: 81.384164 | M34: 79.567935 | N34: 97.664171 | P34: 2303.3161 | Q34: 124.73911 | R34: 104.20148 | S34: 113.59445 | T34: 233.47706 | V34: 0 | W34: 0 | X34: 0 | Y34: 26.239633 | AA34: 0 | AB34: 84.600927 | AC34: 84.1156 | AD34: 114.94626 | AF34: 0 | AG34: 0 | AH34: 0 | AJ34: 0 | AK34: 0 | AM34: 0 | AN34: 0 | AO34: 0 | AQ34: 40.760061 | AR34: 27.586512 | AS34: 1.9042813 | AU34: 0 | AV34: 0 | AW34: 0 | AY34: 168.11849 | AZ34: 2313.8668 | BA34: 24.721162 | BB34: 12.664209 | BD34: 3.9208234 | BE34: 0.54370781 | BF34: 4.845431 | BG34: 3.371756 | BI34: 66.625764 | BJ34: 62.422391 | BK34: 88.668214 | BM34: 25.717137 | BN34: 20.663246 | BO34: 22.109912 | BQ34: 67.684648 | BR34: 13.775672 | BT34: 0 | BU34: 84.322116 | BV34: 18.442964
A36: Ciclo de Caja en Días | D36: 319.09646 | E36: 232.498 | F36: 323.72398 | G36: 326.68427 | H36: 270.85245 | J36: 459.9936 | K36: 313.83109 | L36: 531.75951 | M36: 549.0924 | N36: 493.3455 | P36: 2208.8585 | Q36: 214.45114 | R36: 203.63575 | S36: 254.79371 | T36: 150.86179 | V36: 283.79331 | W36: 201.35668 | X36: 317.63946 | Y36: 137.76631 | AA36: 0 | AB36: 363.6648 | AC36: 256.05874 | AD36: 265.27128 | AM36: 213.61052 | AN36: 243.10167 | AO36: 222.9112 | AQ36: 213.94002 | AR36: 347.76295 | AS36: 318.43391 | AU36: 61.161233 | AV36: 46.739736 | AW36: 40.58706 | AY36: 964.41744 | AZ36: 2282.608 | BA36: 1398.0702 | BB36: 742.38594 | BD36: 292.15775 | BE36: 264.19274 | BF36: 285.29793 | BG36: 443.28542 | BI36: 35.881255 | BJ36: 45.876099 | BK36: 26.05445 | BM36: 199.75223 | BN36: 175.128 | BO36: 227.40012 | BQ36: -16.783045 | BR36: 263.72442 | BT36: 198.75392 | BU36: 230.88741 | BV36: 418.86415
A37: EBITDA | D37: 14418.686 | E37: 2893.883 | F37: 5234.476 | G37: 6219.504 | H37: 3790.438 | J37: 55422 | K37: 49227 | L37: 39552.463 | M37: 32077.02 | N37: 43794.466 | P37: -2481 | Q37: 6022.187 | R37: 5992.457 | S37: 8775.025 | T37: 6049.452 | V37: -35.504 | W37: -2708.358 | X37: 962.143 | Y37: 1111.626 | AA37: 0 | AB37: 4038.452 | AC37: 5892.766 | AD37: 8517.153 | AF37: -0.28 | AG37: 5.53129 | AH37: 1.85184 | AJ37: -421.18522 | AK37: 1232.1515 | AM37: 7601.4172 | AN37: 9028.5853 | AO37: 3695.5195 | AQ37: 10861.364 | AR37: 8190.774 | AS37: 2426.61 | AU37: 49706.997 | AV37: 71647.446 | AW37: 84233.029 | AY37: 344.93039 | AZ37: 1020.6891 | BA37: 3318.0811 | BB37: 5383.7008 | BD37: 101848.72 | BE37: 113646.52 | BF37: 155180.48 | BG37: 130015.49 | BI37: 2752.852 | BJ37: -22928.867 | BK37: 36789.63 | BM37: 2352.6003 | BN37: 3277.0267 | BO37: 4907.7649 | BQ37: 71.14404 | BR37: 273.04545 | BT37: 575.682 | BU37: 2230.289 | BV37: 3575.704
A39: Apalancamiento | D39: 3.5584521 | E39: 2.6971286 | F39: 2.1432751 | G39: 1.843065 | H39: 1.6254711 | J39: 1.0532407 | K39: 1.116007 | L39: 1.1155377 | M39: 1.2258233 | N39: 1.4809159 | P39: 0.59448284 | Q39: 0.73638858 | R39: 0.73450034 | S39: 0.78314926 | T39: 0.97160473 | V39: 1.8865132 | W39: 0.34099863 | X39: 1.303573 | Y39: 1.8242812 | AA39: 0 | AB39: 1.1441519 | AC39: 1.0746918 | AD39: 0.96282684 | AF39: 0.00032585678 | AG39: 0 | AH39: 0 | AJ39: 1.5 | AK39: 3.7396717 | AM39: 1.6593059 | AN39: 1.7780132 | AO39: 1.6731429 | AQ39: 1.1455411 | AR39: 1.5954658 | AS39: 1.3923094 | AU39: 2.9201215 | AV39: 2.596349 | AW39: 2.5653728 | AY39: 0.7749158 | AZ39: 2.4559164 | BA39: 2.2000924 | BB39: 1.6067404 | BD39: 1.5683284 | BE39: 1.6624889 | BF39: 1.8361403 | BG39: 3.0472382 | BI39: 1.9783383 | BJ39: 4.6231274 | BK39: 5.7096122 | BM39: 0.18049472 | BN39: 0.11888758 | BO39: 0.26305017 | BQ39: 4.9546413 | BR39: 6.2425058 | BT39: 0.68050507 | BU39: 3.1871796 | BV39: 2.6703501
A40: Apalancamiento Bancario | J40: 0.84349059 | K40: 0.7977405 | L40: 0.47713848 | M40: 0.51855977 | N40: 0.72933114 | P40: 0.30031508 | Q40: 0.29135624 | R40: 0.21246742 | S40: 0.25251266 | T40: 0.41340849 | V40: 0 | W40: 0 | X40: 0 | Y40: 0 | AA40: 0 | AB40: 0.72252822 | AC40: 0.48523395 | AD40: 0.26793166 | AF40: 0 | AG40: 0 | AH40: 0 | AJ40: 0 | AK40: 0.3961134 | AM40: 1.3458261 | AN40: 1.597841 | AO40: 1.4869946 | AQ40: 0.87882628 | AR40: 1.4355182 | AS40: 1.3685266 | AU40: 2.526328 | AV40: 1.9290997 | AW40: 1.6818468 | AY40: 0.64656207 | AZ40: 1.8104316 | BA40: 2.1650561 | BB40: 1.577394 | BD40: 1.3370244 | BE40: 1.3953067 | BF40: 1.4392421 | BG40: 2.1887275 | BI40: 0 | BJ40: 0 | BK40: 0 | BM40: 0.11060554 | BN40: 0.055420881 | BO40: 0.19207589 | BQ40: 0 | BR40: 4.9399811 | BT40: 0.066756475 | BU40: 0.81907403 | BV40: 2.0655959
A41: Apalancamiento Comercial | D41: 3.5502475 | E41: 2.670022 | F41: 1.9462502 | G41: 1.5135245 | H41: 1.325428 | J41: 0.058175677 | K41: 0.065799838 | L41: 0.10266551 | M41: 0.12294651 | N41: 0.13944219 | P41: 0.051756428 | Q41: 0.053049173 | R41: 0.068203244 | S41: 0.052009655 | T41: 0.061848395 | V41: 1.8690515 | W41: 0.30945095 | X41: 1.246281 | Y41: 1.4969901 | AA41: 0 | AB41: 0.022176606 | AC41: 0.057237927 | AD41: 0 | AF41: 0.00032585678 | AG41: 0 | AH41: 0 | AJ41: 0 | AK41: 0 | AM41: 0.29227166 | AN41: 0.1633062 | AO41: 0.15859124 | AQ41: 0.26071208 | AR41: 0.15496972 | AS41: 0.013363547 | AU41: 0.23363981 | AV41: 0.41717451 | AW41: 0.54720674 | AY41: 0.12792554 | AZ41: 0.64532518 | BA41: 0.034735012 | BB41: 0.029346377 | BD41: 0.057396927 | BE41: 0.024453928 | BF41: 0.03239549 | BG41: 0.030289783 | BI41: 1.3386232 | BJ41: 2.5566283 | BK41: 3.7313155 | BM41: 0.065500736 | BN41: 0.053461735 | BO41: 0.063090372 | BQ41: 4.8745208 | BR41: 0.39619216 | BT41: 0 | BU41: 1.3333417 | BV41: 0.18066865
A42: Crecimiento Anual en Ventas | E42: =E10/D10-1 -> -0.014683192 | F42: =F10/E10-1 -> 0.26351927 | G42: =G10/F10-1 -> 0.099887075 | H42: =H10/G10-1 -> -0.26313757 | K42: =K10/J10-1 -> -0.021981474 | L42: =L10/K10-1 -> 0.093713993 | M42: =M10/L10-1 -> 0.16287436 | N42: =N10/M10-1 -> -0.25648732 | Q42: =Q10/P10-1 -> 15.317158 | R42: =R10/Q10-1 -> 0.47388517 | S42: =S10/R10-1 -> 0.055515009 | T42: =T10/S10-1 -> -0.30836004 | W42: =W10/V10-1 -> 0.65183776 | X42: =X10/W10-1 -> 0.27312921 | Y42: =Y10/X10-1 -> -0.21155038 | AC42: =AC10/AB10-1 -> 0.32625776 | AD42: =AD10/AC10-1 -> 0.044512999 | AH42: -0.025495079 | AM42: 0.26145295 | AN42: 0.10998813 | AO42: 0.013886995 | AR42: -0.16290603 | AS42: 0.14321957 | AV42: 0.6699303 | AW42: 0.29114551 | AZ42: -0.60731184 | BA42: 4.1921338 | BB42: 1.2251217 | BE42: 0.22332825 | BF42: 0.039864852 | BG42: -0.12384191 | BJ42: 0.37032508 | BK42: 0.23661006 | BN42: 0.27679282 | BO42: 0.19778174 | BR42: 0.58620664 | BT42: 0.74440575 | BU42: 0.55845628 | BV42: 0.16549705
A43: ROE | D43: 1.0065572 | E43: 0.16806885 | F43: 0.23313125 | G43: 0.21691592 | H43: 0.12990113 | J43: 0.043241836 | K43: 0.04546603 | L43: 0.030679364 | M43: 0.012837603 | N43: 0.005607463 | P43: -0.02200401 | Q43: 0.0092537229 | R43: 0.018560168 | S43: 0.030907011 | T43: -0.025987756 | V43: -0.0016476775 | W43: -0.14375918 | X43: 0.036399844 | Y43: 0.071731102 | AA43: 0 | AB43: 0.031437952 | AC43: 0.02346664 | AD43: 0.073072603 | AF43: -1.5478136e-05 | AG43: 0.00030602023 | AH43: 0.00020488675 | AJ43: -103.82709 | AK43: 0.48232211 | AM43: 0.16536038 | AN43: 0.15189775 | AO43: 0.13948118 | AQ43: 0.24557448 | AR43: 0.13541065 | AS43: 0.16737406 | AU43: 0.089295699 | AV43: 0.14097556 | AW43: 0.20794676 | AY43: 0.0015574141 | AZ43: 0.052966598 | BA43: 0.14595134 | BB43: 0.17932388 | BD43: 0.0075367171 | BE43: 0.019760951 | BF43: 0.053935268 | BG43: 0.0053655263 | BI43: -0.078354346 | BJ43: -0.38036558 | BK43: 0.10883781 | BM43: 0.15105474 | BN43: 0.17341031 | BO43: 0.20616274 | BQ43: 0.93174815 | BR43: 0.75445923 | BT43: 0.090530202 | BU43: 0.81596515 | BV43: 0.49438479
A44: ROA | D44: 0.22081187 | E44: 0.045459291 | F44: 0.074168262 | G44: 0.076296506 | H44: 0.049477267 | J44: 0.021060233 | K44: 0.021486711 | L44: 0.014501923 | M44: 0.0057675749 | N44: 0.0022602391 | P44: -0.01380003 | Q44: 0.0053292926 | R44: 0.010700585 | S44: 0.017332824 | T44: -0.013181017 | V44: -0.00057081931 | W44: -0.10720072 | X44: 0.015801472 | Y44: 0.025398007 | AA44: 0 | AB44: 0.014662185 | AC44: 0.011310904 | AD44: 0.037228248 | AF44: -1.5473094e-05 | AG44: 0.00030602023 | AH44: 0.00020488675 | AJ44: -41.530835 | AK44: 0.10176277 | AM44: 0.062181784 | AN44: 0.054678555 | AO44: 0.052178722 | AQ44: 0.11445806 | AR44: 0.052172005 | AS44: 0.069963381 | AU44: 0.022778809 | AV44: 0.039199633 | AW44: 0.058323987 | AY44: 0.000877458 | AZ44: 0.015326354 | BA44: 0.045608477 | BB44: 0.068792382 | BD44: 0.0029344835 | BE44: 0.0074219844 | BF44: 0.019017137 | BG44: 0.0013257253 | BI44: -0.026308074 | BJ44: -0.067643067 | BK44: 0.016221178 | BM44: 0.12795884 | BN44: 0.15498457 | BO44: 0.16322609 | BQ44: 0.15647427 | BR44: 0.10417102 | BT44: 0.05387083 | BU44: 0.19487226 | BV44: 0.1346969
A47: CALIFICADOR Z
A49: Inventarios | J49: 82040 | K49: 69549 | L49: 58821.594 | M49: 60654.179 | N49: 152555.97 | P49: 5924 | Q49: 9027.959 | R49: 9936.311 | S49: 11853.918 | T49: 20667.477 | V49: 3481.167 | W49: 2275.958 | X49: 2412.788 | Y49: 5320.602 | AA49: 0 | AB49: 3179.649 | AC49: 4199.378 | AD49: 2754.552 | AK49: 1436.0616 | AM49: 14964.555 | AN49: 15742.367 | AO49: 17221.702 | AQ49: 23678.823 | AR49: 28790.548 | AS49: 26819.743 | AZ49: 2449.5644 | BA49: 3641.5624 | BB49: 8278.4365 | BD49: 149388.94 | BE49: 135129.34 | BF49: 140786.46 | BG49: 274342.42 | BI49: 106027.18 | BJ49: 168857.25 | BK49: 216476.4 | BM49: 225.88182 | BN49: 350.88182 | BO49: 3010.9329
A51: Liquidez Corriente | D51: =ActivoCorr/PasivoCorr -> 0.52567621 | E51: =ActivoCorr/PasivoCorr -> 0.53276511 | F51: =ActivoCorr/PasivoCorr -> 0.71595243 | G51: =ActivoCorr/PasivoCorr -> 0.98873932 | H51: =ActivoCorr/PasivoCorr -> 0.69692044 | J51: =ActivoCorr/PasivoCorr -> 3.0118585 | K51: =ActivoCorr/PasivoCorr -> 2.0829301 | L51: =ActivoCorr/PasivoCorr -> 2.804098 | M51: =ActivoCorr/PasivoCorr -> 2.6957203 | N51: =ActivoCorr/PasivoCorr -> 1.6525435 | P51: =ActivoCorr/PasivoCorr -> 4.4775176 | Q51: =ActivoCorr/PasivoCorr -> 1.1819505 | R51: =ActivoCorr/PasivoCorr -> 1.2920412 | S51: =ActivoCorr/PasivoCorr -> 1.2966328 | T51: =ActivoCorr/PasivoCorr -> 1.0345747 | V51: =ActivoCorr/PasivoCorr -> 0.42192369 | W51: =ActivoCorr/PasivoCorr -> 3.7101485 | X51: =ActivoCorr/PasivoCorr -> 1.6541428 | Y51: =ActivoCorr/PasivoCorr -> 1.0029432 | AB51: =ActivoCorr/PasivoCorr -> 2.5345822 | AC51: =ActivoCorr/PasivoCorr -> 2.2879555 | AD51: =ActivoCorr/PasivoCorr -> 3.6693191 | AJ51: =ActivoCorr/PasivoCorr -> 0.66666667 | AK51: =ActivoCorr/PasivoCorr -> 1.2578721 | AM51: =ActivoCorr/PasivoCorr -> 1.3555077 | AN51: =ActivoCorr/PasivoCorr -> 1.5984283 | AO51: =ActivoCorr/PasivoCorr -> 1.427253 | AQ51: =ActivoCorr/PasivoCorr -> 7.8859179 | AR51: =ActivoCorr/PasivoCorr -> 16.247744 | AS51: =ActivoCorr/PasivoCorr -> 123.43045 | AU51: =ActivoCorr/PasivoCorr -> 11.366419 | AV51: =ActivoCorr/PasivoCorr -> 6.587118 | AW51: =ActivoCorr/PasivoCorr -> 6.5280188 | AY51: =ActivoCorr/PasivoCorr -> 12.274803 | AZ51: =ActivoCorr/PasivoCorr -> 5.0641548 | BA51: =ActivoCorr/PasivoCorr -> 2.9828705 | BB51: =ActivoCorr/PasivoCorr -> 2.9863077 | BD51: =ActivoCorr/PasivoCorr -> 3.430633 | BE51: =ActivoCorr/PasivoCorr -> 3.3810184 | BF51: =ActivoCorr/PasivoCorr -> 3.096237 | BG51: =ActivoCorr/PasivoCorr -> 1.8835925 | BI51: =ActivoCorr/PasivoCorr -> 1.4951827 | BJ51: =ActivoCorr/PasivoCorr -> 1.1905534 | BK51: =ActivoCorr/PasivoCorr -> 1.1356781 | BM51: =ActivoCorr/PasivoCorr -> 12.491584 | BN51: =ActivoCorr/PasivoCorr -> 13.358775 | BO51: =ActivoCorr/PasivoCorr -> 12.948305 | BQ51: =ActivoCorr/PasivoCorr -> 1.1920863 | BR51: =ActivoCorr/PasivoCorr -> 5.5008329 | BT51: =ActivoCorr/PasivoCorr -> 2.4537129 | BU51: =ActivoCorr/PasivoCorr -> 1.3233687 | BV51: =ActivoCorr/PasivoCorr -> 5.6987921
A52: Rotación de Activos | D52: =Ventas/ActivoTotal -> 0.36647316 | E52: =Ventas/ActivoTotal -> 0.37039321 | F52: =Ventas/ActivoTotal -> 0.42213182 | G52: =Ventas/ActivoTotal -> 0.40197607 | H52: =Ventas/ActivoTotal -> 0.23638248 | J52: =Ventas/ActivoTotal -> 0.36568627 | K52: =Ventas/ActivoTotal -> 0.33116867 | L52: =Ventas/ActivoTotal -> 0.32468439 | M52: =Ventas/ActivoTotal -> 0.33556258 | N52: =Ventas/ActivoTotal -> 0.24585832 | P52: =Ventas/ActivoTotal -> 0.019884756 | Q52: =Ventas/ActivoTotal -> 0.29421203 | R52: =Ventas/ActivoTotal -> 0.42957098 | S52: =Ventas/ActivoTotal -> 0.41551161 | T52: =Ventas/ActivoTotal -> 0.26421641 | V52: =Ventas/ActivoTotal -> 0.32839735 | W52: =Ventas/ActivoTotal -> 1.3354797 | X52: =Ventas/ActivoTotal -> 0.95376749 | Y52: =Ventas/ActivoTotal -> 0.58035576 | AB52: =Ventas/ActivoTotal -> 0.496397 | AC52: =Ventas/ActivoTotal -> 0.6641641 | AD52: =Ventas/ActivoTotal -> 0.6824403 | AF52: =Ventas/ActivoTotal -> 0 | AG52: =Ventas/ActivoTotal -> 0.0046655818 | AH52: =Ventas/ActivoTotal -> 0.0022730896 | AJ52: =Ventas/ActivoTotal -> 0 | AK52: =Ventas/ActivoTotal -> 0.42952511 | AM52: =Ventas/ActivoTotal -> 1.1140705 | AN52: =Ventas/ActivoTotal -> 1.0433364 | AO52: =Ventas/ActivoTotal -> 0.55771673 | AQ52: =Ventas/ActivoTotal -> 1.3343134 | AR52: =Ventas/ActivoTotal -> 0.86718503 | AS52: =Ventas/ActivoTotal -> 0.2576415 | AU52: =Ventas/ActivoTotal -> 0.2150808 | AV52: =Ventas/ActivoTotal -> 0.33631266 | AW52: =Ventas/ActivoTotal -> 0.44923041 | AY52: =Ventas/ActivoTotal -> 0.23208384 | AZ52: =Ventas/ActivoTotal -> 0.053823324 | BA52: =Ventas/ActivoTotal -> 0.18294138 | BB52: =Ventas/ActivoTotal -> 0.33810169 | BD52: =Ventas/ActivoTotal -> 0.35902818 | BE52: =Ventas/ActivoTotal -> 0.44701736 | BF52: =Ventas/ActivoTotal -> 0.46648648 | BG52: =Ventas/ActivoTotal -> 0.39779325 | BI52: =Ventas/ActivoTotal -> 2.9727812 | BJ52: =Ventas/ActivoTotal -> 3.0485622 | BK52: =Ventas/ActivoTotal -> 2.815562 | BM52: =Ventas/ActivoTotal -> 1.1453744 | BN52: =Ventas/ActivoTotal -> 1.2715995 | BO52: =Ventas/ActivoTotal -> 1.0710886 | BQ52: =Ventas/ActivoTotal -> 6.9170819 | BR52: =Ventas/ActivoTotal -> 1.7462101 | BT52: =Ventas/ActivoTotal -> 2.0535625 | BU52: =Ventas/ActivoTotal -> 1.9768706 | BV52: =Ventas/ActivoTotal -> 1.6696619
A53: Activo/Patrimonio | D53: =ActivoTotal/Patrimonio -> 4.5584382 | E53: =ActivoTotal/Patrimonio -> 3.6971286 | F53: =ActivoTotal/Patrimonio -> 3.1432751 | G53: =ActivoTotal/Patrimonio -> 2.843065 | H53: =ActivoTotal/Patrimonio -> 2.6254711 | J53: =ActivoTotal/Patrimonio -> 2.0532458 | K53: =ActivoTotal/Patrimonio -> 2.116007 | L53: =ActivoTotal/Patrimonio -> 2.1155377 | M53: =ActivoTotal/Patrimonio -> 2.2258233 | N53: =ActivoTotal/Patrimonio -> 2.4809159 | P53: =ActivoTotal/Patrimonio -> 1.59449 | Q53: =ActivoTotal/Patrimonio -> 1.7363886 | R53: =ActivoTotal/Patrimonio -> 1.7345003 | S53: =ActivoTotal/Patrimonio -> 1.7831493 | T53: =ActivoTotal/Patrimonio -> 1.9716047 | V53: =ActivoTotal/Patrimonio -> 2.8865132 | W53: =ActivoTotal/Patrimonio -> 1.3410281 | X53: =ActivoTotal/Patrimonio -> 2.303573 | Y53: =ActivoTotal/Patrimonio -> 2.8242807 | AB53: =ActivoTotal/Patrimonio -> 2.1441519 | AC53: =ActivoTotal/Patrimonio -> 2.0746918 | AD53: =ActivoTotal/Patrimonio -> 1.9628268 | AF53: =ActivoTotal/Patrimonio -> 1.0003259 | AG53: =ActivoTotal/Patrimonio -> 1 | AH53: =ActivoTotal/Patrimonio -> 1 | AJ53: =ActivoTotal/Patrimonio -> 2.5 | AK53: =ActivoTotal/Patrimonio -> 4.7396717 | AM53: =ActivoTotal/Patrimonio -> 2.6593059 | AN53: =ActivoTotal/Patrimonio -> 2.7780132 | AO53: =ActivoTotal/Patrimonio -> 2.6731429 | AQ53: =ActivoTotal/Patrimonio -> 2.1455411 | AR53: =ActivoTotal/Patrimonio -> 2.5954658 | AS53: =ActivoTotal/Patrimonio -> 2.3923094 | AU53: =ActivoTotal/Patrimonio -> 3.9201215 | AV53: =ActivoTotal/Patrimonio -> 3.596349 | AW53: =ActivoTotal/Patrimonio -> 3.5653728 | AY53: =ActivoTotal/Patrimonio -> 1.7749158 | AZ53: =ActivoTotal/Patrimonio -> 3.4559164 | BA53: =ActivoTotal/Patrimonio -> 3.2000924 | BB53: =ActivoTotal/Patrimonio -> 2.6067404 | BD53: =ActivoTotal/Patrimonio -> 2.5683284 | BE53: =ActivoTotal/Patrimonio -> 2.6624889 | BF53: =ActivoTotal/Patrimonio -> 2.8361403 | BG53: =ActivoTotal/Patrimonio -> 4.0472382 | BI53: =ActivoTotal/Patrimonio -> 2.9783383 | BJ53: =ActivoTotal/Patrimonio -> 5.6231274 | BK53: =ActivoTotal/Patrimonio -> 6.7096122 | BM53: =ActivoTotal/Patrimonio -> 1.1804947 | BN53: =ActivoTotal/Patrimonio -> 1.1188876 | BO53: =ActivoTotal/Patrimonio -> 1.2630502 | BQ53: =ActivoTotal/Patrimonio -> 5.9546413 | BR53: =ActivoTotal/Patrimonio -> 7.2425058 | BT53: =ActivoTotal/Patrimonio -> 1.6805051 | BU53: =ActivoTotal/Patrimonio -> 4.1871796 | BV53: =ActivoTotal/Patrimonio -> 3.6703501
...

Sheet Altman
B2: Tabla Resumida de Rangos de Interpretación | H2: Coeficientes
E3: Bajo Riesgo | F3: Riesgo Moderado | G3: Alto Riesgo | H3: a1 | I3: a2 | J3: a3 | K3: a4 | L3: a5
A4: 1 | B4: Altman Original (1968) – Manufactureras Públicas | C4: 1.81 | D4: 2.99 | E4: Z ≥ 2.99 | F4: 1.81 ≤ Z < 2.99 | G4: Z < 1.81 | H4: 1.2 | I4: 1.4 | J4: 3.3 | K4: 0.6 | L4: 1 | S4: Altman original (1968), empresas manufactureras públicas
A5: 2 | B5: Altman Revisado (1983) – Manufactureras Privadas | C5: 1.23 | D5: 2.9 | E5: Z ≥ 2.90 | F5: 1.23 ≤ Z < 2.90 | G5: Z < 1.23 | H5: 0.717 | I5: 0.847 | J5: 3.107 | K5: 0.42 | L5: 0.998 | S5: Altman revisado (1983), empresas manufactureras privadas
A6: 3 | B6: Z'' para No Manufactureras y Mercados Emergentes | C6: 1.23 | D6: 2.9 | E6: Z ≥ 2.90 | F6: 1.23 ≤ Z < 2.90 | G6: Z < 1.23 | H6: 6.56 | I6: 3.26 | J6: 6.72 | K6: 1.05 | L6: 0 | S6: Altman Z'' para no manufactureras y mercados emergentes (sin ventas/activos)
A7: 4 | B7: Altman Modificado (Ventas Ajustadas) | C7: 1.81 | D7: 2.99 | E7: Z ≥ 2.99 | F7: 1.81 ≤ Z < 2.99 | G7: Z < 1.81 | H7: 1.2 | I7: 1.4 | J7: 3.3 | K7: 0.6 | L7: 0.99 | S7: Altman modificado, empresas públicas (coeficiente de ventas ajustado)
A8: 5 | B8: Z’-Score Revisado para PYMES de Europa Central y Este | C8: 1.23 | D8: 2.9 | E8: Z ≥ 2.90 | F8: 1.23 ≤ Z < 2.90 | G8: Z < 1.23 | H8: 0.717 | I8: 0.847 | J8: 3.107 | K8: 0.42 | L8: 0.998 | S8: Z’-Score revisado, probado en pymes de Europa Central y del Este
A9: 6 | B9: Z''-Score Mercados Emergentes (con constante) | C9: 1.1 | D9: 2.6 | E9: Z ≥ 2.60 | F9: 1.10 ≤ Z < 2.60 | G9: Z < 1.10 | H9: 6.56 | I9: 3.26 | J9: 6.72 | K9: 1.05 | L9: 0 | S9: Z''-Score para mercados emergentes, con constante +3.25
A10: 7 | B10: Pesos Iguales (Propuesta Experimental) | C10: 1.81 | D10: 2.99 | E10: Z ≥ 2.99 | F10: 1.81 ≤ Z < 2.99 | G10: Z < 1.81 | H10: 1 | I10: 1 | J10: 1 | K10: 1 | L10: 1 | S10: Propuesta experimental: pesos iguales para análisis exploratorio
A11: 8 | B11: Ajuste para Empresas Medianas Latinoamericanas | C11: 1.23 | D11: 2.9 | E11: Z ≥ 2.90 | F11: 1.23 ≤ Z < 2.90 | G11: Z < 1.23 | H11: 1.5 | I11: 1 | J11: 2.5 | K11: 0.5 | L11: 1 | S11: Experiencia práctica: ajuste para empresas medianas latinoamericanas (literatura y consultoría)
A14: 1 | B14: 1. Altman Original (1968) – Empresas Manufactureras Públicas
B15: Z < 1.81: Zona de peligro (alto riesgo de quiebra)
B16: 1.81 ≤ Z < 2.99: Zona gris (riesgo moderado)
B17: Z ≥ 2.99: Zona segura (bajo riesgo de quiebra)
A19: 2 | B19: 2. Altman Revisado (1983) – Manufactureras Privadas
B20: Z < 1.23: Zona de peligro (alto riesgo)
B21: 1.23 ≤ Z < 2.90: Zona gris (riesgo moderado)
B22: Z ≥ 2.90: Zona segura (bajo riesgo)
A24: 3 | B24: 3. Z'' para No Manufactureras y Mercados Emergentes
B25: Z < 1.23: Zona de peligro (alto riesgo)
B26: 1.23 ≤ Z < 2.90: Zona gris (riesgo moderado)
B27: Z ≥ 2.90: Zona segura (bajo riesgo)
A29: 4 | B29: 4. Altman Modificado (Ventas Ajustadas)
B30: Z < 1.81: Alto riesgo
B31: 1.81 ≤ Z < 2.99: Riesgo moderado
B32: Z ≥ 2.99: Bajo riesgo
A34: 5 | B34: 5. Z’-Score Revisado para PYMES de Europa Central y del Este
B35: Z < 1.23: Alto riesgo
B36: 1.23 ≤ Z < 2.90: Riesgo moderado
B37: Z ≥ 2.90: Bajo riesgo
A39: 6 | B39: 6. Z''-Score para Mercados Emergentes (con constante)
B40: Z < 1.10: Zona de peligro (alto riesgo)
B41: 1.10 ≤ Z < 2.60: Zona gris (riesgo moderado)
B42: Z ≥ 2.60: Zona segura (bajo riesgo)
A44: 7 | B44: 7. Pesos Iguales (Propuesta Experimental)
B45: Coeficientes: 1.0, 1.0, 1.0, 1.0, 1.0
B46: Z < 1.81: Alto riesgo
B47: 1.81 ≤ Z < 2.99: Riesgo moderado
B48: Z ≥ 2.99: Bajo riesgo
B50: 8. Ajuste para Empresas Medianas Latinoamericanas
...

Sheet Caratula_V2
B1: LU3-American Medical Enterprises v3.xlsx | I1: LU4-Novoswiss PFJuridica v3.xlsx | O1: LU2-Luminova PFJuridica v3.xlsx | T1: LU1-Helvetia PFJuridica v3.xlsx | Y1: ETI-Corp Etisa 2025 vf.xlsx
A2: LU3-American Medical Enterprises v3.xlsx | B2: 2020 | C2: 2021 | D2: 2022 | E2: 2023 | F2: 2024 | H2: 2020 | I2: 2021 | J2: 2022 | K2: 2023 | L2: 2024 | N2: 2020 | O2: 2021 | P2: 2022 | Q2: 2023 | R2: 2024 | T2: 2021 | U2: 2022 | V2: 2023 | W2: 2024 | Y2: 2021 | Z2: 2022 | AA2: 2023 | AB2: 2024
B3: Auditado | C3: Auditado | D3: Auditado | E3: Auditado | F3: Admin. | H3: Auditado | I3: Auditado | J3: Auditado | K3: Auditado | L3: Admin. | N3: Auditado | O3: Auditado | P3: Auditado | Q3: Admin. | R3: Admin. | T3: Auditado | U3: Auditado | V3: Auditado | W3: Admin. | Y3: Pendiente | Z3: Auditado | AA3: Auditado | AB3: Admin.
A5: NOMBRE DEL CLIENTE: American Medical Enterprises, Inc.
A6: GIRO DEL NEGOCIO:
A7: EN MILES DE: DÓLARES
A8: AUDITOR O CONTADOR ACTIVO: Axel Samuel Rosas
A10: Ventas | B10: 23930.151 | C10: 23578.78 | D10: 29792.243 | E10: 32768.103 | F10: 24145.584 | H10: 337466 | I10: 330048 | J10: 360978.12 | K10: 419772.2 | L10: 312105.95 | N10: 4317 | O10: 70441.169 | P10: 103822.19 | Q10: 109585.88 | R10: 75793.976 | T10: 20425.762 | U10: 33740.045 | V10: 42955.437 | W10: 33868.198 | Y10: 0 | Z10: 39281.699 | AA10: 52097.658 | AB10: 54416.681
A11: Utilidad Neta | B11: 14418.686 | C11: 2893.883 | D11: 5234.476 | E11: 6219.504 | F11: 3790.438 | H11: 19435 | I11: 21414 | J11: 16122.97 | K11: 7214.951 | L11: 2151.953 | N11: -2996 | O11: 1275.956 | P11: 2586.204 | Q11: 4571.311 | R11: -2835.862 | T11: -35.504 | U11: -2708.358 | V11: 711.661 | W11: 1111.626 | Y11: 0 | Z11: 1160.272 | AA11: 887.238 | AB11: 2968.52
A14: Activo Corriente | B14: 21443.876 | C14: 16147.77 | D14: 27257.998 | E14: 30188.632 | F14: 28923.839 | H14: 489171 | I14: 559173 | J14: 658388.66 | K14: 747714.18 | L14: 731542.08 | N14: 156739.98 | O14: 50343.569 | P14: 69251.927 | Q14: 80296.962 | R14: 89011.252 | T14: 17118.68 | U14: 22603.33 | V14: 41829.318 | W14: 22008.315 | Y14: 4149 | Z14: 55862.546 | AA14: 47567.44 | AB14: 53771.717
A15: Activo No Corriente | B15: 0 | C15: 0 | D15: 0 | E15: 0 | F15: 0 | H15: 117278.28 | I15: 105337 | J15: 183901.7 | K15: 221052.02 | L15: 95615.306 | N15: 25948 | O15: 26300.778 | P15: 23715.271 | Q15: 28567.047 | R15: 29221.778 | T15: 45079.636 | U15: 2661.033 | V15: 3208.322 | W15: 5083.783 | Y15: 0 | Z15: 11951.704 | AA15: 10657.175 | AB15: 10971.355
A16: Activo Diferido | B16: 43854.634 | C16: 47511.01 | D16: 43317.688 | E16: 51328.915 | F16: 73222.413 | H16: 316380 | I16: 332106 | J16: 269491.19 | K16: 282184.37 | L16: 442297.11 | N16: 34413 | O16: 162778.8 | P16: 148720.9 | Q16: 154873.23 | R16: 168630.21 | T16: 0 | U16: 0 | V16: 0 | W16: 31265.551 | Y16: 0 | Z16: 11319.385 | AA16: 20216.327 | AB16: 14995.304
A17: Total de Activo | B17: 65298.51 | C17: 63658.78 | D17: 70575.686 | E17: 81517.547 | F17: 102146.25 | H17: 922829.28 | I17: 996616 | J17: 1111781.5 | K17: 1250950.6 | L17: 1269454.5 | N17: 217100.98 | O17: 239423.14 | P17: 241688.1 | Q17: 263737.24 | R17: 286863.24 | T17: 62198.316 | U17: 25264.363 | V17: 45037.64 | W17: 58357.649 | Y17: 4149 | Z17: 79133.635 | AA17: 78440.942 | AB17: 79738.376
A19: Pasivo Corriente | B19: 40792.936 | C19: 30309.361 | D19: 38072.359 | E19: 30532.448 | F19: 41502.354 | H19: 162415 | I19: 268455 | J19: 234795.17 | K19: 277370.83 | L19: 442676.45 | N19: 35006 | O19: 42593.636 | P19: 53598.854 | Q19: 61927.296 | R19: 86036.563 | T19: 40572.929 | U19: 6092.298 | V19: 25287.61 | W19: 21943.731 | Y19: 0 | Z19: 22040.14 | AA19: 20790.369 | AB19: 14654.413
A20: Pasivo No Corriente | B20: 10181.019 | C20: 16130.981 | D20: 10050.413 | E20: 22312.681 | F20: 21738.022 | H20: 310963 | I20: 257172 | J20: 351454.95 | K20: 411562.72 | L20: 315090.21 | N20: 45937 | O20: 58943.814 | P20: 48747.619 | Q20: 53904.635 | R20: 55329.341 | T20: 77.481 | U20: 331.962 | V20: 198.82 | W20: 15751.093 | Y20: 0 | Z20: 20186.765 | AA20: 19842.093 | AB20: 24459.709
A21: Total Pasivo | B21: 50973.955 | C21: 46440.342 | D21: 48122.772 | E21: 52845.129 | F21: 63240.376 | H21: 473378 | I21: 525627 | J21: 586250.12 | K21: 688933.55 | L21: 757766.65 | N21: 80943 | O21: 101537.45 | P21: 102346.47 | Q21: 115831.93 | R21: 141365.9 | T21: 40650.41 | U21: 6424.26 | V21: 25486.43 | W21: 37694.824 | Y21: 0 | Z21: 42226.905 | AA21: 40632.462 | AB21: 39114.122
A23: Capital | B23: 0.2 | C23: 0.2 | D23: 0.2 | E23: 0.2 | F23: 0.2 | H23: 114975 | I23: 114995 | J23: 114995 | K23: 114995 | L23: 114995 | N23: 128348 | O23: 128370.97 | P23: 128397.93 | Q23: 128397.93 | R23: 128414.01 | T23: 21388 | U23: 21388 | V23: 21388 | W23: 21388 | Y23: 0 | Z23: 20598 | AA23: 20598 | AB23: 20598
A24: Otros | B24: 0 | C24: 0 | D24: 0 | E24: 0 | F24: 0 | H24: 0 | I24: 0 | J24: -6800.427 | K24: 22470.203 | L24: 0 | N24: 6984 | O24: 7515.611 | P24: 1254.59 | Q24: 949.485 | R24: 3094.496 | T24: 0 | U24: 0 | V24: 0 | W24: 0 | Y24: 0 | Z24: 0 | AA24: 0 | AB24: 5439.5
A25: Reserva Legal | H25: 28309 | I25: 29652 | J25: 31064.837 | K25: 31778.92 | L25: 31778.92 | N25: 3668 | O25: 3835.227 | P25: 4086.595 | Q25: 4175.852 | R25: 4541.229 | T25: 71.441 | U25: 71.441 | V25: 119.549 | W25: 119.549 | Y25: 0 | Z25: 0 | AA25: 0 | AB25: 694.589
A26: Utilidades Retenidas | B26: 14324.555 | C26: 17218.238 | D26: 22452.714 | E26: 28672.218 | F26: 38905.676 | H26: 306165 | I26: 326342 | J26: 386272.01 | K26: 392772.88 | L26: 364913.92 | N26: -2843 | O26: -1836.117 | P26: 360.338 | Q26: 8745.705 | R26: -4538.771 | T26: 88.465 | U26: -2619.893 | V26: -1956.339 | W26: -844.713 | Y26: 0 | Z26: 16308.73 | AA26: 17210.48 | AB26: 13892.165
A27: Total Patrimonio | B27: 14324.755 | C27: 17218.438 | D27: 22452.914 | E27: 28672.418 | F27: 38905.876 | H27: 449449 | I27: 470989 | J27: 525531.42 | K27: 562017 | L27: 511687.84 | N27: 136157 | O27: 137885.69 | P27: 139341.63 | Q27: 147905.31 | R27: 145497.34 | T27: 21547.906 | U27: 18839.548 | V27: 19551.21 | W27: 20662.836 | Y27: 0 | Z27: 36906.73 | AA27: 37808.48 | AB27: 40624.254
A30: Liquidez | B30: 0.52567621 | C30: 0.53276511 | D30: 0.71595243 | E30: 0.98873932 | F30: 0.69692044 | H30: 3.0118585 | I30: 2.0829301 | J30: 2.804098 | K30: 2.6957203 | L30: 1.6525435 | N30: 4.4775176 | O30: 1.1819505 | P30: 1.2920412 | Q30: 1.2966328 | R30: 1.0345747 | T30: 0.42192369 | U30: 3.7101485 | V30: 1.6541428 | W30: 1.0029432 | Y30: 0 | Z30: 2.5345822 | AA30: 2.2879555 | AB30: 3.6693191
A31: Prueba Acida | B31: 0.52567489 | C31: 0.53276498 | D31: 0.71595243 | E31: 0.98873932 | F31: 0.69692044 | H31: 2.3167996 | I31: 1.7105176 | J31: 2.458597 | K31: 2.3510577 | L31: 1.3079216 | N31: 4.1072668 | O31: 0.83911521 | P31: 0.97149027 | Q31: 0.9002935 | R31: 0.79435734 | T31: 0.33612345 | U31: 2.8278118 | V31: 1.4480697 | W31: 0.76047747 | Y31: 0 | Z31: 1.9549913 | AA31: 1.6244756 | AB31: 2.729427
A32: Capital de Trabajo | B32: -19349.06 | C32: -14161.591 | D32: -10814.361 | E32: -343.816 | F32: -12578.515 | H32: 326756 | I32: 290718 | J32: 423593.49 | K32: 470343.34 | L32: 288865.64 | N32: 121733.98 | O32: 7749.933 | P32: 15653.073 | Q32: 18369.666 | R32: 2974.689 | T32: -23454.249 | U32: 16511.032 | V32: 16541.708 | W32: 64.584 | Y32: 4149 | Z32: 33822.406 | AA32: 26777.071 | AB32: 39117.304
A35: Período promedio de cobro (días) | B35: 319.0952 | C35: 232.49789 | D35: 323.72398 | E35: 326.68427 | F35: 281.4713 | H35: 256.00126 | I35: 239.33791 | J35: 487.77804 | K35: 488.48729 | L35: 370.59914 | N35: 2608.4781 | O35: 119.01166 | P35: 125.78658 | Q35: 134.70208 | R35: 165.75094 | T35: 215.46244 | U35: 141.40689 | V35: 262.41122 | W35: 106.72672 | Y35: 0 | Z35: 281.77593 | AA35: 205.37245 | AB35: 245.89489
A36: Rotación promedio de inventario (días) | B36: 0.0012572104 | C36: 0.00011149442 | D36: 0 | E36: 0 | F36: 0 | H36: 268.7454 | I36: 178.57197 | J36: 125.36564 | K36: 140.17304 | L36: 220.41053 | N36: 1903.6965 | O36: 220.17859 | P36: 182.05065 | Q36: 233.68608 | R36: 218.58791 | T36: 68.330869 | U36: 59.949788 | V36: 55.228232 | W36: 57.279224 | Y36: 0 | Z36: 166.4898 | AA36: 134.80189 | AB36: 134.32265
A37: Período promedio de pago (días) | B37: 0 | C37: 0 | D37: 0 | E37: 0 | F37: 10.618845 | H37: 64.753056 | I37: 104.0788 | J37: 81.384164 | K37: 79.567935 | L37: 97.664171 | N37: 2303.3161 | O37: 124.73911 | P37: 104.20148 | Q37: 113.59445 | R37: 233.47706 | T37: 0 | U37: 0 | V37: 0 | W37: 26.239633 | Y37: 0 | Z37: 84.600927 | AA37: 84.1156 | AB37: 114.94626
A40: Ciclo de Caja en Días | B40: 319.09646 | C40: 232.498 | D40: 323.72398 | E40: 326.68427 | F40: 270.85245 | H40: 459.9936 | I40: 313.83109 | J40: 531.75951 | K40: 549.0924 | L40: 493.3455 | N40: 2208.8585 | O40: 214.45114 | P40: 203.63575 | Q40: 254.79371 | R40: 150.86179 | T40: 283.79331 | U40: 201.35668 | V40: 317.63946 | W40: 137.76631 | Y40: 0 | Z40: 363.6648 | AA40: 256.05874 | AB40: 265.27128
A42: Apalancamiento | B42: 3.5584521 | C42: 2.6971286 | D42: 2.1432751 | E42: 1.843065 | F42: 1.6254711 | H42: 1.0532407 | I42: 1.116007 | J42: 1.1155377 | K42: 1.2258233 | L42: 1.4809159 | N42: 0.59448284 | O42: 0.73638858 | P42: 0.73450034 | Q42: 0.78314926 | R42: 0.97160473 | T42: 1.8865132 | U42: 0.34099863 | V42: 1.303573 | W42: 1.8242812 | Y42: 0 | Z42: 1.1441519 | AA42: 1.0746918 | AB42: 0.96282684
A43: Apalancamiento Bancario | B43: 0 | C43: 0 | D43: 0 | E43: 0 | F43: 0 | H43: 0.84349059 | I43: 0.7977405 | J43: 0.47713848 | K43: 0.51855977 | L43: 0.72933114 | N43: 0.30031508 | O43: 0.29135624 | P43: 0.21246742 | Q43: 0.25251266 | R43: 0.41340849 | T43: 0 | U43: 0 | V43: 0 | W43: 0 | Y43: 0 | Z43: 0.72252822 | AA43: 0.48523395 | AB43: 0.26793166
A44: Apalancamiento Comercial | B44: 3.5502475 | C44: 2.670022 | D44: 1.9462502 | E44: 1.5135245 | F44: 1.325428 | H44: 0.058175677 | I44: 0.065799838 | J44: 0.10266551 | K44: 0.12294651 | L44: 0.13944219 | N44: 0.051756428 | O44: 0.053049173 | P44: 0.068203244 | Q44: 0.052009655 | R44: 0.061848395 | T44: 1.8690515 | U44: 0.30945095 | V44: 1.246281 | W44: 1.4969901 | Y44: 0 | Z44: 0.022176606 | AA44: 0.057237927 | AB44: 0
A45: Crecimiento Anual en Ventas
A46: ROE | B46: 1.0065572 | C46: 0.16806885 | D46: 0.23313125 | E46: 0.21691592 | F46: 0.12990113 | H46: 0.043241836 | I46: 0.04546603 | J46: 0.030679364 | K46: 0.012837603 | L46: 0.005607463 | N46: -0.02200401 | O46: 0.0092537229 | P46: 0.018560168 | Q46: 0.030907011 | R46: -0.025987756 | T46: -0.0016476775 | U46: -0.14375918 | V46: 0.036399844 | W46: 0.071731102 | Y46: 0 | Z46: 0.031437952 | AA46: 0.02346664 | AB46: 0.073072603
A47: ROA | B47: 0.22081187 | C47: 0.045459291 | D47: 0.074168262 | E47: 0.076296506 | F47: 0.049477267 | H47: 0.021060233 | I47: 0.021486711 | J47: 0.014501923 | K47: 0.0057675749 | L47: 0.0022602391 | N47: -0.01380003 | O47: 0.0053292926 | P47: 0.010700585 | Q47: 0.017332824 | R47: -0.013181017 | T47: -0.00057081931 | U47: -0.10720072 | V47: 0.015801472 | W47: 0.025398007 | Y47: 0 | Z47: 0.014662185 | AA47: 0.011310904 | AB47: 0.037228248
A48: EBITDA | B48: 14418.686 | C48: 2893.883 | D48: 5234.476 | E48: 6219.504 | F48: 3790.438 | H48: 55422 | I48: 49227 | J48: 39552.463 | K48: 32077.02 | L48: 43794.466 | N48: -2481 | O48: 6022.187 | P48: 5992.457 | Q48: 8775.025 | R48: 6049.452 | T48: -35.504 | U48: -2708.358 | V48: 962.143 | W48: 1111.626 | Y48: 0 | Z48: 4038.452 | AA48: 5892.766 | AB48: 8517.153

Sheet Balance
K1: LU4-Novoswiss PFJuridica v3 | S1: LU2-Luminova PFJuridica v3 | Z1: LU1-Helvetia PFJuridica v3.xlsx | AG1: ETI-Corp Etisa 2025 vf.xlsx | AO1: Bahía Colorada | AU1: Soluciones Carnicas.xlsm | AZ1: Servicios y Percederos.xlsm | BF1: Quimica Total.xlsm | BL1: Logistica Nave.xlsm | BR1: Inv_Iginla | BY1: Ing_Palo_Gordo | CF1: Distrib_Me_Llega | CL1: Corinco | CR1: Inversiones Mapakhan, S.A. | CW1: CorpMogori
A2: LU3-American Medical Enterprises v3.xlsx | C2: 2020 | D2: 2021 | E2: 2022 | F2: 2023 | G2: 2024 | I2: LU4-Novoswiss PFJuridica v3.xlsx | K2: 2020 | L2: 2021 | M2: 2022 | N2: 2023 | O2: 2024 | Q2: LU2-Luminova PFJuridica v3.xlsx | S2: 2020 | T2: 2021 | U2: 2022 | V2: 2023 | W2: 2024 | Y2: LU1-Helvetia PFJuridica v3.xlsx | AA2: 2021 | AB2: 2022 | AC2: 2023 | AD2: 2024 | AF2: ETI-Corp Etisa 2025 vf.xlsx | AH2: 2021 | AI2: 2022 | AJ2: 2023 | AK2: 2024 | AM2: Bahía Colorada.xlsx | AO2: 2021 | AP2: 2022 | AQ2: 2023 | AS2: Soluciones Carnicas.xlsm | AU2: 2022 | AV2: 2023 | AX2: Servicios y Percederos.xlsm | AZ2: 2021 | BA2: 2022 | BB2: 2023 | BD2: Quimica Total.xlsm | BF2: 2022 | BG2: 2023 | BH2: 2024 | BJ2: Logistica Nave.xlsm | BL2: 2022 | BM2: 2023 | BN2: 2024 | BP2: Inv_Iginla.xlsm | BR2: 2020 | BS2: 2021 | BT2: 2022 | BU2: 2023 | BW2: Ing_Palo_Gordo.xlsx | BY2: 2021 | BZ2: 2022 | CA2: 2023 | CB2: 2024 | CD2: Distrib_Me_Llega.xlsx | CF2: 2022 | CG2: 2023 | CH2: 2024 | CJ2: Corinco.xlsx | CL2: 2021 | CM2: 2022 | CN2: 2023 | CP2: InvM.xlsx | CR2: 2021 | CS2: 2022 | CU2: CorpMogori.xlsx | CW2: 2021 | CX2: 2022 | CY2: 2023 | CZ2: 2024
A4: Meses considerados | C4: 12 | D4: 12 | E4: 12 | F4: 12 | G4: 9 | K4: 12 | L4: 12 | M4: 12 | N4: 12 | O4: 9 | S4: 12 | T4: 12 | U4: 12 | V4: 12 | W4: 9 | AA4: 12 | AB4: 12 | AC4: 12 | AD4: 9 | AH4: 12 | AI4: 12 | AJ4: 12 | AK4: 12 | AO4: 12 | AP4: 12 | AQ4: 6 | AU4: 12 | AV4: 8 | AZ4: 12 | BA4: 12 | BB4: 6 | BF4: 12 | BG4: 12 | BH4: 3 | BL4: 12 | BM4: 12 | BN4: 12 | BR4: 12 | BS4: 12 | BT4: 12 | BU4: 12 | BY4: 12 | BZ4: 12 | CA4: 12 | CB4: 12 | CF4: 12 | CG4: 12 | CH4: 12 | CL4: 12 | CM4: 12 | CN4: 12 | CR4: 12 | CS4: 12 | CW4: 12 | CX4: 12 | CY4: 12 | CZ4: 5
C5: Auditado | D5: Auditado | E5: Auditado | F5: Auditado | G5: Admin. | K5: Auditado | L5: Auditado | M5: Auditado | N5: Auditado | O5: Admin. | S5: Auditado | T5: Auditado | U5: Auditado | V5: Admin. | W5: Admin. | AA5: Auditado | AB5: Auditado | AC5: Auditado | AD5: Admin. | AH5: Pendiente | AI5: Auditado | AJ5: Auditado | AK5: Admin. | AO5: Auditado | AP5: Auditado | AQ5: Administrativo | AU5: Administrativo | AV5: Administrativo | AZ5: Auditado | BA5: Auditado | BB5: Administrativo | BF5: Administrativo | BG5: Administrativo | BH5: Administrativo | BL5: Auditado | BM5: Auditado | BN5: Administrativo | BR5: Auditado | BS5: Auditado | BT5: Auditado | BU5: Auditado | BY5: Auditado | BZ5: Auditado | CA5: Auditado | CB5: Administrativo | CF5: Auditado | CG5: Auditado | CH5: Administrativo | CL5: Administrativo | CM5: Administrativo | CN5: Administrativo | CR5: Administrativo | CS5: Administrativo | CW5: Administrativo | CX5: Administrativo | CY5: Administrativo | CZ5: Administrativo
C6: Deloitte | D6: Deloitte | E6: Deloitte | F6: Deloitte | G6: Axel Samuel Rosas | K6: Miguel Angel Imul Gracia | L6: Miguel Angel Imul Gracia | M6: Deloitte | N6: Deloitte | O6: Axel Rosas y Edgar Locón S. | S6: PWR | T6: Deloitte | U6: Deloitte | V6: Deloitte | W6: Axel Rosas (cpa) y Michael Erichsen R (rep) | AB6: Deloitte | AC6: Deloitte | AD6: Axel S. Rosas S. (cpa) y Humberto Gonzalez (rep) | AI6: Nuñez Bubón y Asociados | AJ6: Nuñez Bubón y Asociados | AK6: Mynor Armando Alacan Morales | AO6: Lic. Edwin R. Hernandez B. | AP6: Lic. Edwin R. Hernandez B. | AQ6: Maria Eliza Rodas Morales | AU6: Hugo Waldermar Sutuj Chamale | AV6: Hugo Waldermar Sutuj Chamale | AZ6: Jorge Eduardo Granillo Díaz | BA6: Jorge Eduardo Granillo Díaz | BB6: Lesly Mariela de León Ruiz | BF6: Jorge Eduardo Motta Morales | BG6: Jorge Eduardo Motta Morales | BH6: Jorge Eduardo Motta Morales | BL6: Nexia | BM6: Nexia | BN6: Edgar Culajay | BR6: Lic. Oscar Saul Rodríguez Lemus | BS6: Lic. Oscar Saul Rodríguez Lemus | BT6: Lic. Oscar Saul Rodríguez Lemus | BU6: Lic. Oscar Saul Rodríguez Lemus | BY6: PKF | BZ6: PKF | CA6: PKF | CB6: MARVIN ROBERTO CANO TEPEU | CF6: Nexia | CG6: Nexia | CH6: Edgar Estuardo Culajay Pirir | CL6: Miguel Miculax Olcot | CM6: Miguel Miculax Olcot | CN6: Miguel Miculax Olcot | CR6: Sergio Armando Mancilla López | CS6: Sergio Armando Mancilla López | CW6: Sergio Armando Mancilla López | CX6: Sergio Armando Mancilla López | CY6: Sergio Armando Mancilla López | CZ6: Sergio Armando Mancilla López
